Workbook

Sheet Absensi APR - GPN B 
A1: No | B1: Nama Lengkap | D1: Tanggal Hadir | J1: Akumulasi Kehadiran | K1: Jumlah Pertemuan | L1: Presentase
C2: Kategori
A3: =ROW()-ROW($A$1) -> 2 | C3: APR | J3: =COUNTA(D3:I3) -> 0 | K3: 4 | L3: =J3/K3 -> 0
A4: =ROW()-ROW($A$1) -> 3 | C4: APR | J4: =COUNTA(D4:I4) -> 0 | K4: 4 | L4: =J4/K4 -> 0
A5: =ROW()-ROW($A$1) -> 4 | C5: APR | J5: =COUNTA(D5:I5) -> 0 | K5: 4 | L5: =J5/K5 -> 0
A6: Total | J6: =SUM(J3:J5) -> 0 | K6: =SUM(K3:K5) -> 12 | L6: =AVERAGE(L3:L5) -> 0
A8: =ROW()-ROW($A$7) -> 1 | C8: AR | J8: =COUNTA(D8:I8) -> 0 | K8: 4 | L8: =J8/K8 -> 0
A9: =ROW()-ROW($A$7) -> 2 | C9: AR | J9: =COUNTA(D9:I9) -> 0 | K9: 4 | L9: =J9/K9 -> 0
A10: =ROW()-ROW($A$7) -> 3 | C10: AR | J10: =COUNTA(D10:I10) -> 0 | K10: 4 | L10: =J10/K10 -> 0
A11: =ROW()-ROW($A$7) -> 4 | C11: AR | J11: =COUNTA(D11:I11) -> 0 | K11: 4 | L11: =J11/K11 -> 0
A12: =ROW()-ROW($A$7) -> 5 | C12: AR | J12: =COUNTA(D12:I12) -> 0 | K12: 4 | L12: =J12/K12 -> 0
A13: Total | J13: =SUM(J8:J12) -> 0 | K13: =SUM(K8:K12) -> 20 | L13: =AVERAGE(L8:L12) -> 0
A15: =ROW()-ROW($A$14) -> 1 | C15: GPNA | J15: =COUNTA(D15:I15) -> 0 | K15: 4 | L15: =J15/K15 -> 0
A16: =ROW()-ROW($A$14) -> 2 | C16: GPNA | J16: =COUNTA(D16:I16) -> 0 | K16: 4 | L16: =J16/K16 -> 0
A17: =ROW()-ROW($A$14) -> 3 | C17: GPNA | J17: =COUNTA(D17:I17) -> 0 | K17: 4 | L17: =J17/K17 -> 0
A18: =ROW()-ROW($A$14) -> 4 | C18: GPNA | J18: =COUNTA(D18:I18) -> 0 | K18: 4 | L18: =J18/K18 -> 0
A19: =ROW()-ROW($A$14) -> 5 | C19: GPNA | J19: =COUNTA(D19:I19) -> 0 | K19: 4 | L19: =J19/K19 -> 0
A20: =ROW()-ROW($A$14) -> 6 | C20: GPNA | J20: =COUNTA(D20:I20) -> 0 | K20: 4 | L20: =J20/K20 -> 0
A21: =ROW()-ROW($A$14) -> 7 | C21: GPNA | J21: =COUNTA(D21:I21) -> 0 | K21: 4 | L21: =J21/K21 -> 0
A22: =ROW()-ROW($A$14) -> 8 | C22: GPNA | J22: =COUNTA(D22:I22) -> 0 | K22: 4 | L22: =J22/K22 -> 0
A23: =ROW()-ROW($A$14) -> 9 | C23: GPNA | J23: =COUNTA(D23:I23) -> 0 | K23: 4 | L23: =J23/K23 -> 0
A24: =ROW()-ROW($A$14) -> 10 | C24: GPNA | J24: =COUNTA(D24:I24) -> 0 | K24: 4 | L24: =J24/K24 -> 0
A25: =ROW()-ROW($A$14) -> 11 | C25: GPNA | J25: =COUNTA(D25:I25) -> 0 | K25: 4 | L25: =J25/K25 -> 0
A26: =ROW()-ROW($A$14) -> 12 | C26: GPNA | J26: =COUNTA(D26:I26) -> 0 | K26: 4 | L26: =J26/K26 -> 0
A27: =ROW()-ROW($A$14) -> 13 | C27: GPNA | J27: =COUNTA(D27:I27) -> 0 | K27: 4 | L27: =J27/K27 -> 0
A28: Total | J28: =SUM(J15:J27) -> 0 | K28: =SUM(K15:K27) -> 52 | L28: =AVERAGE(L15:L27) -> 0
A30: =ROW()-ROW($A$29) -> 1 | C30: GPNB | J30: =COUNTA(D30:I30) -> 0 | K30: 4 | L30: =J30/K30 -> 0
A31: =ROW()-ROW($A$29) -> 2 | C31: GPNB | J31: =COUNTA(D31:I31) -> 0 | K31: 4 | L31: =J31/K31 -> 0
A32: =ROW()-ROW($A$29) -> 3 | C32: GPNB | J32: =COUNTA(D32:I32) -> 0 | K32: 4 | L32: =J32/K32 -> 0
A33: =ROW()-ROW($A$29) -> 4 | C33: GPNB | J33: =COUNTA(D33:I33) -> 0 | K33: 4 | L33: =J33/K33 -> 0
A34: =ROW()-ROW($A$29) -> 5 | C34: GPNB | J34: =COUNTA(D34:I34) -> 0 | K34: 4 | L34: =J34/K34 -> 0
A35: =ROW()-ROW($A$29) -> 6 | C35: GPNB | J35: =COUNTA(D35:I35) -> 0 | K35: 4 | L35: =J35/K35 -> 0
A36: =ROW()-ROW($A$29) -> 7 | C36: GPNB | J36: =COUNTA(D36:I36) -> 0 | K36: 4 | L36: =J36/K36 -> 0
A37: =ROW()-ROW($A$29) -> 8 | C37: GPNB | J37: =COUNTA(D37:I37) -> 0 | K37: 4 | L37: =J37/K37 -> 0
A38: =ROW()-ROW($A$29) -> 9 | C38: GPNB | J38: =COUNTA(D38:I38) -> 0 | K38: 4 | L38: =J38/K38 -> 0
A39: =ROW()-ROW($A$29) -> 10 | C39: GPNB | J39: =COUNTA(D39:I39) -> 0 | K39: 4 | L39: =J39/K39 -> 0
A40: =ROW()-ROW($A$29) -> 11 | C40: GPNB | J40: =COUNTA(D40:I40) -> 0 | K40: 4 | L40: =J40/K40 -> 0
A41: Total | J41: =SUM(J30:J40) -> 0 | K41: =SUM(K30:K40) -> 44 | L41: =AVERAGE(L30:L40) -> 0
A43: Total Akumulasi Kehadiran & Presentase | J43: =SUM(J6+J13+J28+J41) -> 0 | K43: =SUM(K6+K13+K28+K41) -> 128 | L43: =AVERAGE(L6,L13,L28,L41) -> 0
B46: HADIR
...

Sheet Absensi AR Intensif
A1: No | B1: Nama Lengkap | C1: Tanggal Absen | K1: Akumulasi Hadir | L1: Jumlah Pertemuan | M1: Presentase
A3: =ROW()-ROW('Absensi APR - GPN B '!$A$1) -> 2 | K3: =COUNTA(C3:J3) -> 0 | L3: 4 | M3: =K3/L3 -> 0
A4: =ROW()-ROW('Absensi APR - GPN B '!$A$1) -> 3 | K4: =COUNTA(C4:J4) -> 0 | L4: 4 | M4: =K4/L4 -> 0
A5: =ROW()-ROW('Absensi APR - GPN B '!$A$1) -> 4 | K5: =COUNTA(C5:J5) -> 0 | L5: 4 | M5: =K5/L5 -> 0
A6: =ROW()-ROW('Absensi APR - GPN B '!$A$1) -> 5 | K6: =COUNTA(C6:J6) -> 0 | L6: 4 | M6: =K6/L6 -> 0
A7: =ROW()-ROW('Absensi APR - GPN B '!$A$1) -> 6 | K7: =COUNTA(C7:J7) -> 0 | L7: 4 | M7: =K7/L7 -> 0
A8: Total Akumulasi Hadir & Presentase | K8: =SUM(K3:K7) -> 0 | L8: =SUM(L3:L7) -> 20 | M8: =AVERAGE(M4:M7) -> 0
B12: HADIR
B13: IZIN
B14: ALPHA

Sheet Absensi ACR
A1: No | B1: Nama Lengkap | C1: Tanggal | K1: Akumulasi Hadir | L1: Jumlah Pertemuan | M1: Presentase
A3: =ROW()-ROW('Absensi APR - GPN B '!$A$1) -> 2 | K3: =COUNTA(C3:J3) -> 0 | L3: 4 | M3: =K3/L3 -> 0
A4: =ROW()-ROW('Absensi APR - GPN B '!$A$1) -> 3 | K4: =COUNTA(C4:J4) -> 0 | L4: 4 | M4: =K4/L4 -> 0
A5: =ROW()-ROW('Absensi APR - GPN B '!$A$1) -> 4 | K5: =COUNTA(C5:J5) -> 0 | L5: 4 | M5: =K5/L5 -> 0
A6: =ROW()-ROW('Absensi APR - GPN B '!$A$1) -> 5 | K6: =COUNTA(C6:J6) -> 0 | L6: 4 | M6: =K6/L6 -> 0
A7: =ROW()-ROW('Absensi APR - GPN B '!$A$1) -> 6 | K7: =COUNTA(C7:J7) -> 0 | L7: 4 | M7: =K7/L7 -> 0
A8: =ROW()-ROW('Absensi APR - GPN B '!$A$1) -> 7 | K8: =COUNTA(C8:J8) -> 0 | L8: 4 | M8: =K8/L8 -> 0
A9: Total Akumulasi Hadir & Presentase | K9: =SUM(K3:K8) -> 0 | L9: =SUM(L3:L8) -> 24 | M9: =AVERAGE(M4:M8) -> 0
B12: HADIR
B13: IZIN
B14: ALPHA

Sheet Pengajian Desa
A1: No | B1: Nama Lengkap | C1: Tanggal Absen | K1: Akumulasi Hadir | L1: Jumlah Pertemuan | M1: Presentase
A3: =ROW()-ROW('Absensi APR - GPN B '!$A$1) -> 2 | K3: =COUNTA(C3:J3) -> 0 | L3: 4 | M3: =K3/L3 -> 0
A4: =ROW()-ROW('Absensi APR - GPN B '!$A$1) -> 3 | K4: =COUNTA(C4:J4) -> 0 | L4: 4 | M4: =K4/L4 -> 0
A5: =ROW()-ROW('Absensi APR - GPN B '!$A$1) -> 4 | K5: =COUNTA(C5:J5) -> 0 | L5: 4 | M5: =K5/L5 -> 0
A6: =ROW()-ROW('Absensi APR - GPN B '!$A$1) -> 5 | K6: =COUNTA(C6:J6) -> 0 | L6: 4 | M6: =K6/L6 -> 0
A7: =ROW()-ROW('Absensi APR - GPN B '!$A$1) -> 6 | K7: =COUNTA(C7:J7) -> 0 | L7: 4 | M7: =K7/L7 -> 0
A8: Total Akumulasi Hadir & Presentase | K8: =SUM(K3:K7) -> 0 | L8: =SUM(L3:L7) -> 20 | M8: =AVERAGE(M4:M7) -> 0
B11: HADIR
B12: IZIN
B13: ALPHA

Sheet Pengajian Daerah
A1: No | B1: Nama Lengkap | C1: Tanggal Absen | K1: Akumulasi Hadir | L1: Jumlah Pertemuan | M1: Presentase
A3: =ROW()-ROW('Absensi APR - GPN B '!$A$1) -> 2 | K3: =COUNTA(C3:J3) -> 0 | L3: 4 | M3: =K3/L3 -> 0
A4: =ROW()-ROW('Absensi APR - GPN B '!$A$1) -> 3 | K4: =COUNTA(C4:J4) -> 0 | L4: 4 | M4: =K4/L4 -> 0
A5: =ROW()-ROW('Absensi APR - GPN B '!$A$1) -> 4 | K5: =COUNTA(C5:J5) -> 0 | L5: 4 | M5: =K5/L5 -> 0
A6: =ROW()-ROW('Absensi APR - GPN B '!$A$1) -> 5 | K6: =COUNTA(C6:J6) -> 0 | L6: 4 | M6: =K6/L6 -> 0
A7: =ROW()-ROW('Absensi APR - GPN B '!$A$1) -> 6 | K7: =COUNTA(C7:J7) -> 0 | L7: 4 | M7: =K7/L7 -> 0
A8: Total Akumulasi Hadir & Presentase | K8: =SUM(K3:K7) -> 0 | L8: =SUM(L3:L7) -> 20 | M8: =AVERAGE(M4:M7) -> 0
B11: HADIR
B12: IZIN
B13: ALPHA

Sheet Absen Generus Baru
A1: No | B1: Nama Lengkap | C1: Tanggal Absen | K1: Akumulasi Hadir | L1: Jumlah Pertemuan | M1: Presentase
A3: =ROW()-ROW('Absensi APR - GPN B '!$A$1) -> 2 | K3: =COUNTA(C3:J3) -> 0 | L3: 4 | M3: =K3/L3 -> 0
A4: =ROW()-ROW('Absensi APR - GPN B '!$A$1) -> 3 | K4: =COUNTA(C4:J4) -> 0 | L4: 4 | M4: =K4/L4 -> 0
A5: =ROW()-ROW('Absensi APR - GPN B '!$A$1) -> 4 | K5: =COUNTA(C5:J5) -> 0 | L5: 4 | M5: =K5/L5 -> 0
A6: =ROW()-ROW('Absensi APR - GPN B '!$A$1) -> 5 | K6: =COUNTA(C6:J6) -> 0 | L6: 4 | M6: =K6/L6 -> 0
A7: =ROW()-ROW('Absensi APR - GPN B '!$A$1) -> 6 | K7: =COUNTA(C7:J7) -> 0 | L7: 4 | M7: =K7/L7 -> 0
A8: Total Akumulasi Hadir & Presentase | K8: =SUM(K3:K7) -> 0 | L8: =SUM(L3:L7) -> 20 | M8: =AVERAGE(M4:M7) -> 0
B11: HADIR
B12: IZIN
B13: ALPHA
